Workbook

Sheet Leia-me
A1: HIDRO: planilha da oficina com agentes e pesquisadores
A3: Para que serve | B3: Reunir as respostas dos instrumentos da oficina e calcular automaticamente: médias antes e depois, concordância por item, índice de validade de conteúdo (I-CVI) e resumo das observações técnicas.
A4: Como usar | B4: 1) Cada participante recebe um código (P01, P02...). 2) Digite as respostas na aba "Participantes" (uma linha por participante). 3) Digite as notas dos especialistas na aba "Validacao_IVC" (uma coluna por especialista, E1, E2...). 4) Registre as observações na aba "Observacoes". 5) Veja os resultados e os gráficos na aba "Resumo".
A5: Onde digitar | B5: Somente nas células de fundo amarelo e letras azuis. Não digite nas células com fórmulas (fundo branco ou cinza).
A6: Escalas | B6: Confiança, experiência, intenção e utilidade: 1 a 5 (1 = discordo totalmente; 5 = concordo totalmente). Validação de conteúdo: 1 a 4 (1 = inadequado; 2 = precisa de revisão importante; 3 = adequado com pequenos ajustes; 4 = totalmente adequado).
A7: Itens negativos | B7: Na experiência, os itens 7 e 8 (desconforto e incômodo com sons e luzes) são negativos: notas altas indicam mais desconforto. Não os some aos demais.
A8: I-CVI | B8: Número de especialistas que deram nota 3 ou 4 ÷ número de especialistas que avaliaram o item. Referência: até 5 especialistas, exige-se 1,00; com 6 ou mais, I-CVI ≥ 0,78 (Lynn, 1986). Índice geral (S-CVI/Ave): média dos I-CVI, referência ≥ 0,90 (Polit; Beck, 2006).
A9: Exemplo | B9: Item A1 avaliado por 8 especialistas com as notas 4, 4, 3, 4, 3, 4, 2, 4: 7 deram nota 3 ou 4, então I-CVI = 7 ÷ 8 = 0,88, acima de 0,78: "Adequado".
A10: Privacidade | B10: Não digite nomes nem e-mails. Use apenas os códigos. Guarde a lista de correspondência (se existir) separada desta planilha.
A11: Limites | B11: As escalas de confiança e experiência foram elaboradas para esta oficina e não foram validadas. Uma turma de oficina é uma amostra pequena e de conveniência: apresente os resultados de forma descritiva e sem generalizar.
A13: Legenda de cores
A14: Digite aqui | B14: Células de entrada (fundo amarelo, letras azuis)
A15: Calculado | B15: Células com fórmulas (não digite)

Sheet Resumo
A1: Resumo dos resultados
A2: Tudo nesta aba é calculado automaticamente. Não digite aqui.
A4: Participantes com respostas | B4: =COUNTA(Participantes!A7:A56) -> 0
A6: Confiança para usar jogos em ações educativas (média, escala de 1 a 5)
A7: Item | B7: Média pré | C7: Média pós | D7: Diferença
A8: Item 1: Sei explicar a estudantes do ensino fundamental a diferença entre alagamento, enxurrada, enchente e deslizamento. | B8: =IFERROR(AVERAGE(Participantes!G7:G56),"") | C8: =IFERROR(AVERAGE(Participantes!L7:L56),"") | D8: =IF(OR(B8="",C8=""),"",C8-B8)
A9: Item 2: Sei como um jogo digital pode ser usado em uma ação educativa sobre riscos de desastres. | B9: =IFERROR(AVERAGE(Participantes!H7:H56),"") | C9: =IFERROR(AVERAGE(Participantes!M7:M56),"") | D9: =IF(OR(B9="",C9=""),"",C9-B9)
A10: Item 3: Consigo planejar uma atividade com o HIDRO em parceria com uma escola. | B10: =IFERROR(AVERAGE(Participantes!I7:I56),"") | C10: =IFERROR(AVERAGE(Participantes!N7:N56),"") | D10: =IF(OR(B10="",C10=""),"",C10-B10)
A11: Item 4: Sei adaptar uma atividade educativa para estudantes autistas ou com altas habilidades. | B11: =IFERROR(AVERAGE(Participantes!J7:J56),"") | C11: =IFERROR(AVERAGE(Participantes!O7:O56),"") | D11: =IF(OR(B11="",C11=""),"",C11-B11)
A12: Item 5: Sei como avaliar se uma ação educativa com jogo foi efetiva. | B12: =IFERROR(AVERAGE(Participantes!K7:K56),"") | C12: =IFERROR(AVERAGE(Participantes!P7:P56),"") | D12: =IF(OR(B12="",C12=""),"",C12-B12)
A13: Média geral dos cinco itens | B13: =IFERROR(AVERAGE(B8:B12),"") | C13: =IFERROR(AVERAGE(C8:C12),"") | D13: =IF(OR(B13="",C13=""),"",C13-B13)
A15: Experiência com o jogo (1 a 5). Itens 7 e 8 são negativos
A16: Item | B16: Média | C16: % de concordância (notas 4 e 5) | D16: Respostas
A17: 1. Foi fácil entender o que eu precisava fazer no jogo. | B17: =IFERROR(AVERAGE(Participantes!Q7:Q56),"") | C17: =IFERROR(COUNTIF(Participantes!Q7:Q56,">=4")/COUNT(Participantes!Q7:Q56),"") | D17: =COUNT(Participantes!Q7:Q56) -> 0
A18: 2. Os controles foram fáceis de usar. | B18: =IFERROR(AVERAGE(Participantes!R7:R56),"") | C18: =IFERROR(COUNTIF(Participantes!R7:R56,">=4")/COUNT(Participantes!R7:R56),"") | D18: =COUNT(Participantes!R7:R56) -> 0
A19: 3. Os textos foram claros. | B19: =IFERROR(AVERAGE(Participantes!S7:S56),"") | C19: =IFERROR(COUNTIF(Participantes!S7:S56,">=4")/COUNT(Participantes!S7:S56),"") | D19: =COUNT(Participantes!S7:S56) -> 0
A20: 4. O jogo prendeu a minha atenção. | B20: =IFERROR(AVERAGE(Participantes!T7:T56),"") | C20: =IFERROR(COUNTIF(Participantes!T7:T56,">=4")/COUNT(Participantes!T7:T56),"") | D20: =COUNT(Participantes!T7:T56) -> 0
A21: 5. O jogo me fez refletir sobre as decisões em uma emergência. | B21: =IFERROR(AVERAGE(Participantes!U7:U56),"") | C21: =IFERROR(COUNTIF(Participantes!U7:U56,">=4")/COUNT(Participantes!U7:U56),"") | D21: =COUNT(Participantes!U7:U56) -> 0
A22: 6. O tempo de cada fase foi adequado. | B22: =IFERROR(AVERAGE(Participantes!V7:V56),"") | C22: =IFERROR(COUNTIF(Participantes!V7:V56,">=4")/COUNT(Participantes!V7:V56),"") | D22: =COUNT(Participantes!V7:V56) -> 0
A23: 7. Senti-me desconfortável ou sobrecarregado(a) em algum momento. | B23: =IFERROR(AVERAGE(Participantes!W7:W56),"") | C23: =IFERROR(COUNTIF(Participantes!W7:W56,">=4")/COUNT(Participantes!W7:W56),"") | D23: =COUNT(Participantes!W7:W56) -> 0
A24: 8. Os sons, as luzes ou os efeitos me incomodaram. | B24: =IFERROR(AVERAGE(Participantes!X7:X56),"") | C24: =IFERROR(COUNTIF(Participantes!X7:X56,">=4")/COUNT(Participantes!X7:X56),"") | D24: =COUNT(Participantes!X7:X56) -> 0
A25: 9. O jogo é adequado para estudantes do 6º ao 9º ano. | B25: =IFERROR(AVERAGE(Participantes!Y7:Y56),"") | C25: =IFERROR(COUNTIF(Participantes!Y7:Y56,">=4")/COUNT(Participantes!Y7:Y56),"") | D25: =COUNT(Participantes!Y7:Y56) -> 0
A26: 10. Eu recomendaria o jogo a professores e escolas. | B26: =IFERROR(AVERAGE(Participantes!Z7:Z56),"") | C26: =IFERROR(COUNTIF(Participantes!Z7:Z56,">=4")/COUNT(Participantes!Z7:Z56),"") | D26: =COUNT(Participantes!Z7:Z56) -> 0
A28: Intenção de uso e utilidade percebida (1 a 5)
A29: Item | B29: Média | C29: % de concordância (notas 4 e 5) | D29: Respostas
A30: Intenção: Pretendo apresentar o HIDRO a escolas ou professores com quem atuo. | B30: =IFERROR(AVERAGE(Participantes!AA7:AA56),"") | C30: =IFERROR(COUNTIF(Participantes!AA7:AA56,">=4")/COUNT(Participantes!AA7:AA56),"") | D30: =COUNT(Participantes!AA7:AA56) -> 0
A31: Intenção: Usaria o jogo em uma ação educativa (palestra, oficina, semana de prevenção). | B31: =IFERROR(AVERAGE(Participantes!AB7:AB56),"") | C31: =IFERROR(COUNTIF(Participantes!AB7:AB56,">=4")/COUNT(Participantes!AB7:AB56),"") | D31: =COUNT(Participantes!AB7:AB56) -> 0
A32: Intenção: Gostaria de participar de um estudo sobre o uso do jogo. | B32: =IFERROR(AVERAGE(Participantes!AC7:AC56),"") | C32: =IFERROR(COUNTIF(Participantes!AC7:AC56,">=4")/COUNT(Participantes!AC7:AC56),"") | D32: =COUNT(Participantes!AC7:AC56) -> 0
A33: Utilidade: O jogo complementa as ações educativas que eu já realizo ou conheço. | B33: =IFERROR(AVERAGE(Participantes!AD7:AD56),"") | C33: =IFERROR(COUNTIF(Participantes!AD7:AD56,">=4")/COUNT(Participantes!AD7:AD56),"") | D33: =COUNT(Participantes!AD7:AD56) -> 0
A34: Utilidade: O plano de aula e as atividades facilitam a aplicação com uma turma. | B34: =IFERROR(AVERAGE(Participantes!AE7:AE56),"") | C34: =IFERROR(COUNTIF(Participantes!AE7:AE56,">=4")/COUNT(Participantes!AE7:AE56),"") | D34: =COUNT(Participantes!AE7:AE56) -> 0
A35: Utilidade: O Modo Professor ajuda a acompanhar as decisões e a aprendizagem. | B35: =IFERROR(AVERAGE(Participantes!AF7:AF56),"") | C35: =IFERROR(COUNTIF(Participantes!AF7:AF56,">=4")/COUNT(Participantes!AF7:AF56),"") | D35: =COUNT(Participantes!AF7:AF56) -> 0
A37: Validação de conteúdo (I-CVI)
A38: Dimensão | B38: S-CVI/Ave (média dos I-CVI) | C38: Itens a revisar | D38: Itens avaliados
A39: A. Precisão técnica dos conceitos | B39: =IFERROR(AVERAGEIF(Validacao_IVC!B5:B28,"Precisão técnica dos conceitos",Validacao_IVC!Z5:Z28),"") | C39: =COUNTIFS(Validacao_IVC!B5:B28,"Precisão técnica dos conceitos",Validacao_IVC!AB5:AB28,"Revisar") -> 0 | D39: =COUNTIFS(Validacao_IVC!B5:B28,"Precisão técnica dos conceitos",Validacao_IVC!X5:X28,">0") -> 0
A40: B. Protocolo de autoproteção | B40: =IFERROR(AVERAGEIF(Validacao_IVC!B5:B28,"Protocolo de autoproteção",Validacao_IVC!Z5:Z28),"") | C40: =COUNTIFS(Validacao_IVC!B5:B28,"Protocolo de autoproteção",Validacao_IVC!AB5:AB28,"Revisar") -> 0 | D40: =COUNTIFS(Validacao_IVC!B5:B28,"Protocolo de autoproteção",Validacao_IVC!X5:X28,">0") -> 0
A41: C. Cenários e situações do jogo | B41: =IFERROR(AVERAGEIF(Validacao_IVC!B5:B28,"Cenários e situações do jogo",Validacao_IVC!Z5:Z28),"") | C41: =COUNTIFS(Validacao_IVC!B5:B28,"Cenários e situações do jogo",Validacao_IVC!AB5:AB28,"Revisar") -> 0 | D41: =COUNTIFS(Validacao_IVC!B5:B28,"Cenários e situações do jogo",Validacao_IVC!X5:X28,">0") -> 0
A42: D. Linguagem e mensagens | B42: =IFERROR(AVERAGEIF(Validacao_IVC!B5:B28,"Linguagem e mensagens",Validacao_IVC!Z5:Z28),"") | C42: =COUNTIFS(Validacao_IVC!B5:B28,"Linguagem e mensagens",Validacao_IVC!AB5:AB28,"Revisar") -> 0 | D42: =COUNTIFS(Validacao_IVC!B5:B28,"Linguagem e mensagens",Validacao_IVC!X5:X28,">0") -> 0
A43: E. Adequação pedagógica | B43: =IFERROR(AVERAGEIF(Validacao_IVC!B5:B28,"Adequação pedagógica",Validacao_IVC!Z5:Z28),"") | C43: =COUNTIFS(Validacao_IVC!B5:B28,"Adequação pedagógica",Validacao_IVC!AB5:AB28,"Revisar") -> 0 | D43: =COUNTIFS(Validacao_IVC!B5:B28,"Adequação pedagógica",Validacao_IVC!X5:X28,">0") -> 0
A44: F. Aplicabilidade e inclusão | B44: =IFERROR(AVERAGEIF(Validacao_IVC!B5:B28,"Aplicabilidade e inclusão",Validacao_IVC!Z5:Z28),"") | C44: =COUNTIFS(Validacao_IVC!B5:B28,"Aplicabilidade e inclusão",Validacao_IVC!AB5:AB28,"Revisar") -> 0 | D44: =COUNTIFS(Validacao_IVC!B5:B28,"Aplicabilidade e inclusão",Validacao_IVC!X5:X28,">0") -> 0
A45: Geral (todos os itens) | B45: =IFERROR(AVERAGE(Validacao_IVC!Z5:Z28),"") | C45: =COUNTIF(Validacao_IVC!AB5:AB28,"Revisar") -> 0 | D45: =COUNTIF(Validacao_IVC!X5:X28,">0") -> 0
...

Sheet Participantes
A1: Respostas dos participantes
A2: Digite apenas nas células amarelas, uma linha por participante. A linha cinza é um exemplo e não entra nos cálculos.
G4: Confiança (1 a 5) | Q4: Experiência com o jogo (1 a 5) | AA4: Intenção de uso (1 a 5) | AD4: Utilidade (1 a 5)
A5: Código | B5: Atuação | C5: Vínculo | D5: Tempo de atuação | E5: Já atuou em escolas? | F5: Já usou jogos digitais? | G5: Pré 1 | H5: Pré 2 | I5: Pré 3 | J5: Pré 4 | K5: Pré 5 | L5: Pós 1 | M5: Pós 2 | N5: Pós 3 | O5: Pós 4 | P5: Pós 5 | Q5: Exp 1 | R5: Exp 2 | S5: Exp 3 | T5: Exp 4 | U5: Exp 5 | V5: Exp 6 | W5: Exp 7 | X5: Exp 8 | Y5: Exp 9 | Z5: Exp 10 | AA5: Int 1 | AB5: Int 2 | AC5: Int 3 | AD5: Util 1 | AE5: Util 2 | AF5: Util 3 | AG5: Média pré | AH5: Média pós | AI5: Diferença
A6: EX | B6: Agente de defesa civil | C6: Municipal | D6: 6 a 10 anos | E6: Sim | F6: Não | G6: 2 | H6: 3 | I6: 2 | J6: 1 | K6: 2 | L6: 4 | M6: 4 | N6: 4 | O6: 3 | P6: 3 | Q6: 5 | R6: 4 | S6: 4 | T6: 4 | U6: 5 | V6: 2 | W6: 1 | X6: 4 | Y6: 5 | Z6: 4 | AA6: 5 | AB6: 4 | AC6: 4 | AD6: 4 | AE6: 4 | AF6: 4 | AG6: =AVERAGE(G6:K6) -> 2 | AH6: =AVERAGE(L6:P6) -> 3.6 | AI6: =AH6-AG6 -> 1.6
AG7: =IF(COUNT(G7:K7)=0,"",AVERAGE(G7:K7)) | AH7: =IF(COUNT(L7:P7)=0,"",AVERAGE(L7:P7)) | AI7: =IF(OR(AG7="",AH7=""),"",AH7-AG7)
AG8: =IF(COUNT(G8:K8)=0,"",AVERAGE(G8:K8)) | AH8: =IF(COUNT(L8:P8)=0,"",AVERAGE(L8:P8)) | AI8: =IF(OR(AG8="",AH8=""),"",AH8-AG8)
AG9: =IF(COUNT(G9:K9)=0,"",AVERAGE(G9:K9)) | AH9: =IF(COUNT(L9:P9)=0,"",AVERAGE(L9:P9)) | AI9: =IF(OR(AG9="",AH9=""),"",AH9-AG9)
AG10: =IF(COUNT(G10:K10)=0,"",AVERAGE(G10:K10)) | AH10: =IF(COUNT(L10:P10)=0,"",AVERAGE(L10:P10)) | AI10: =IF(OR(AG10="",AH10=""),"",AH10-AG10)
AG11: =IF(COUNT(G11:K11)=0,"",AVERAGE(G11:K11)) | AH11: =IF(COUNT(L11:P11)=0,"",AVERAGE(L11:P11)) | AI11: =IF(OR(AG11="",AH11=""),"",AH11-AG11)
AG12: =IF(COUNT(G12:K12)=0,"",AVERAGE(G12:K12)) | AH12: =IF(COUNT(L12:P12)=0,"",AVERAGE(L12:P12)) | AI12: =IF(OR(AG12="",AH12=""),"",AH12-AG12)
AG13: =IF(COUNT(G13:K13)=0,"",AVERAGE(G13:K13)) | AH13: =IF(COUNT(L13:P13)=0,"",AVERAGE(L13:P13)) | AI13: =IF(OR(AG13="",AH13=""),"",AH13-AG13)
AG14: =IF(COUNT(G14:K14)=0,"",AVERAGE(G14:K14)) | AH14: =IF(COUNT(L14:P14)=0,"",AVERAGE(L14:P14)) | AI14: =IF(OR(AG14="",AH14=""),"",AH14-AG14)
AG15: =IF(COUNT(G15:K15)=0,"",AVERAGE(G15:K15)) | AH15: =IF(COUNT(L15:P15)=0,"",AVERAGE(L15:P15)) | AI15: =IF(OR(AG15="",AH15=""),"",AH15-AG15)
AG16: =IF(COUNT(G16:K16)=0,"",AVERAGE(G16:K16)) | AH16: =IF(COUNT(L16:P16)=0,"",AVERAGE(L16:P16)) | AI16: =IF(OR(AG16="",AH16=""),"",AH16-AG16)
AG17: =IF(COUNT(G17:K17)=0,"",AVERAGE(G17:K17)) | AH17: =IF(COUNT(L17:P17)=0,"",AVERAGE(L17:P17)) | AI17: =IF(OR(AG17="",AH17=""),"",AH17-AG17)
AG18: =IF(COUNT(G18:K18)=0,"",AVERAGE(G18:K18)) | AH18: =IF(COUNT(L18:P18)=0,"",AVERAGE(L18:P18)) | AI18: =IF(OR(AG18="",AH18=""),"",AH18-AG18)
... AG56: =IF(COUNT(G56:K56)=0,"",AVERAGE(G56:K56)) | AH56: =IF(COUNT(L56:P56)=0,"",AVERAGE(L56:P56)) | AI56: =IF(OR(AG56="",AH56=""),"",AH56-AG56)

Sheet Validacao_IVC
A1: Validação de conteúdo por especialistas (I-CVI)
A2: Digite as notas de 1 a 4 nas colunas E1 a E20 (um especialista por coluna). Deixe em branco o item que o especialista não avaliou.
A4: Item | B4: Dimensão | C4: Texto do item | D4: E1 | E4: E2 | F4: E3 | G4: E4 | H4: E5 | I4: E6 | J4: E7 | K4: E8 | L4: E9 | M4: E10 | N4: E11 | O4: E12 | P4: E13 | Q4: E14 | R4: E15 | S4: E16 | T4: E17 | U4: E18 | V4: E19 | W4: E20 | X4: Nº de avaliações | Y4: Nº com nota 3 ou 4 | Z4: I-CVI | AA4: Média das notas | AB4: Situação
A5: A1 | B5: Precisão técnica dos conceitos | C5: A definição e a diferenciação de alagamento, enxurrada, enchente (inundação) e deslizamento estão corretas. | X5: =COUNT(D5:W5) -> 0 | Y5: =COUNTIF(D5:W5,">=3") -> 0 | Z5: =IF(X5=0,"",Y5/X5) | AA5: =IF(X5=0,"",AVERAGE(D5:W5)) | AB5: =IF(X5=0,"",IF(X5<=5,IF(Z5=1,"Adequado","Revisar"),IF(Z5>=0.78,"Adequado","Revisar")))
A6: A2 | B6: Precisão técnica dos conceitos | C6: A explicação de infiltração, escoamento superficial e microdrenagem está correta e adequada ao público. | X6: =COUNT(D6:W6) -> 0 | Y6: =COUNTIF(D6:W6,">=3") -> 0 | Z6: =IF(X6=0,"",Y6/X6) | AA6: =IF(X6=0,"",AVERAGE(D6:W6)) | AB6: =IF(X6=0,"",IF(X6<=5,IF(Z6=1,"Adequado","Revisar"),IF(Z6>=0.78,"Adequado","Revisar")))
A7: A3 | B7: Precisão técnica dos conceitos | C7: Os termos técnicos (boca de lobo, poço de visita, tampão, galeria de águas pluviais, cota do rio, talude) estão usados corretamente, com o nome popular indicado. | X7: =COUNT(D7:W7) -> 0 | Y7: =COUNTIF(D7:W7,">=3") -> 0 | Z7: =IF(X7=0,"",Y7/X7) | AA7: =IF(X7=0,"",AVERAGE(D7:W7)) | AB7: =IF(X7=0,"",IF(X7<=5,IF(Z7=1,"Adequado","Revisar"),IF(Z7>=0.78,"Adequado","Revisar")))
A8: A4 | B8: Precisão técnica dos conceitos | C8: Os sinais de alerta (rachaduras, árvore ou poste inclinado, estalos, subida do rio) estão corretos. | X8: =COUNT(D8:W8) -> 0 | Y8: =COUNTIF(D8:W8,">=3") -> 0 | Z8: =IF(X8=0,"",Y8/X8) | AA8: =IF(X8=0,"",AVERAGE(D8:W8)) | AB8: =IF(X8=0,"",IF(X8<=5,IF(Z8=1,"Adequado","Revisar"),IF(Z8>=0.78,"Adequado","Revisar")))
A9: B1 | B9: Protocolo de autoproteção | C9: A sequência proteja-se, avise a Defesa Civil (199) e aja com segurança é adequada ao público-alvo. | X9: =COUNT(D9:W9) -> 0 | Y9: =COUNTIF(D9:W9,">=3") -> 0 | Z9: =IF(X9=0,"",Y9/X9) | AA9: =IF(X9=0,"",AVERAGE(D9:W9)) | AB9: =IF(X9=0,"",IF(X9<=5,IF(Z9=1,"Adequado","Revisar"),IF(Z9>=0.78,"Adequado","Revisar")))
A10: B2 | B10: Protocolo de autoproteção | C10: As orientações sobre energia elétrica (desligar o disjuntor antes de a água atingir as tomadas) estão corretas. | X10: =COUNT(D10:W10) -> 0 | Y10: =COUNTIF(D10:W10,">=3") -> 0 | Z10: =IF(X10=0,"",Y10/X10) | AA10: =IF(X10=0,"",AVERAGE(D10:W10)) | AB10: =IF(X10=0,"",IF(X10<=5,IF(Z10=1,"Adequado","Revisar"),IF(Z10>=0.78,"Adequado","Revisar")))
A11: B3 | B11: Protocolo de autoproteção | C11: As orientações de não entrar na água, não voltar para buscar objetos e evacuar cedo estão corretas. | X11: =COUNT(D11:W11) -> 0 | Y11: =COUNTIF(D11:W11,">=3") -> 0 | Z11: =IF(X11=0,"",Y11/X11) | AA11: =IF(X11=0,"",AVERAGE(D11:W11)) | AB11: =IF(X11=0,"",IF(X11<=5,IF(Z11=1,"Adequado","Revisar"),IF(Z11>=0.78,"Adequado","Revisar")))
A12: B4 | B12: Protocolo de autoproteção | C12: A mochila de emergência e o Cartão de Emergência trazem itens e orientações adequados. | X12: =COUNT(D12:W12) -> 0 | Y12: =COUNTIF(D12:W12,">=3") -> 0 | Z12: =IF(X12=0,"",Y12/X12) | AA12: =IF(X12=0,"",AVERAGE(D12:W12)) | AB12: =IF(X12=0,"",IF(X12<=5,IF(Z12=1,"Adequado","Revisar"),IF(Z12>=0.78,"Adequado","Revisar")))
A13: B5 | B13: Protocolo de autoproteção | C13: Os números de telefone citados (199, 193, 192 e 190) e as menções a alertas estão corretos ou são adaptáveis ao município. | X13: =COUNT(D13:W13) -> 0 | Y13: =COUNTIF(D13:W13,">=3") -> 0 | Z13: =IF(X13=0,"",Y13/X13) | AA13: =IF(X13=0,"",AVERAGE(D13:W13)) | AB13: =IF(X13=0,"",IF(X13<=5,IF(Z13=1,"Adequado","Revisar"),IF(Z13>=0.78,"Adequado","Revisar")))
A14: C1 | B14: Cenários e situações do jogo | C14: A fase de alagamento representa de forma realista a situação e as decisões possíveis. | X14: =COUNT(D14:W14) -> 0 | Y14: =COUNTIF(D14:W14,">=3") -> 0 | Z14: =IF(X14=0,"",Y14/X14) | AA14: =IF(X14=0,"",AVERAGE(D14:W14)) | AB14: =IF(X14=0,"",IF(X14<=5,IF(Z14=1,"Adequado","Revisar"),IF(Z14>=0.78,"Adequado","Revisar")))
A15: C2 | B15: Cenários e situações do jogo | C15: A fase de enxurrada representa de forma realista o perigo da correnteza e a rota segura. | X15: =COUNT(D15:W15) -> 0 | Y15: =COUNTIF(D15:W15,">=3") -> 0 | Z15: =IF(X15=0,"",Y15/X15) | AA15: =IF(X15=0,"",AVERAGE(D15:W15)) | AB15: =IF(X15=0,"",IF(X15<=5,IF(Z15=1,"Adequado","Revisar"),IF(Z15>=0.78,"Adequado","Revisar")))
A16: C3 | B16: Cenários e situações do jogo | C16: A fase de enchente representa de forma realista a subida do rio e o tempo disponível para agir. | X16: =COUNT(D16:W16) -> 0 | Y16: =COUNTIF(D16:W16,">=3") -> 0 | Z16: =IF(X16=0,"",Y16/X16) | AA16: =IF(X16=0,"",AVERAGE(D16:W16)) | AB16: =IF(X16=0,"",IF(X16<=5,IF(Z16=1,"Adequado","Revisar"),IF(Z16>=0.78,"Adequado","Revisar")))
... A28: F3 | B28: Aplicabilidade e inclusão | C28: As opções de acessibilidade (modo calmo, som e alto contraste) são adequadas. | X28: =COUNT(D28:W28) -> 0 | Y28: =COUNTIF(D28:W28,">=3") -> 0 | Z28: =IF(X28=0,"",Y28/X28) | AA28: =IF(X28=0,"",AVERAGE(D28:W28)) | AB28: =IF(X28=0,"",IF(X28<=5,IF(Z28=1,"Adequado","Revisar"),IF(Z28>=0.78,"Adequado","Revisar")))

Sheet Observacoes
A1: Observações técnicas (durante o jogo)
A2: Uma linha por observação. A linha cinza é um exemplo e não entra nos cálculos.
A4: Nº | B4: Participante ou dupla | C4: Fase ou tela | D4: O que observou | E4: Tipo | F4: Gravidade | G4: Sugestão | H4: Decisão
A5: 0 | B5: P03 | C5: Fase 1 | D5: Exemplo: o texto do glossário poderia citar também o termo "galeria de águas pluviais". | E5: Terminologia | F5: Baixa | G5: Incluir o termo no glossário. | H5: Ajustar
A6: 1
A7: 2
A8: 3
A9: 4
A10: 5
A11: 6
A12: 7
A13: 8
A14: 9
A15: 10
A16: 11
A17: 12
... A65: 60
